ERROR:sqlalchemy.pool.impl.QueuePool:Exception during reset or similar
Traceback (most recent call last):
  File "C:\Users\singh\AppData\Local\Packages\PythonSoftwareFoundation.Python.3.11_qbz5n2kfra8p0\LocalCache\local-packages\Python311\site-packages\sqlalchemy\pool\base.py", line 987, in _finalize_fairy
    fairy._reset(
  File "C:\Users\singh\AppData\Local\Packages\PythonSoftwareFoundation.Python.3.11_qbz5n2kfra8p0\LocalCache\local-packages\Python311\site-packages\sqlalchemy\pool\base.py", line 1433, in _reset
    pool._dialect.do_rollback(self)
  File "C:\Users\singh\AppData\Local\Packages\PythonSoftwareFoundation.Python.3.11_qbz5n2kfra8p0\LocalCache\local-packages\Python311\site-packages\sqlalchemy\engine\default.py", line 703, in do_rollback
    dbapi_connection.rollback()
  File "C:\Users\singh\AppData\Local\Packages\PythonSoftwareFoundation.Python.3.11_qbz5n2kfra8p0\LocalCache\local-packages\Python311\site-packages\pymysql\connections.py", line 493, in rollback
    self._read_ok_packet()
  File "C:\Users\singh\AppData\Local\Packages\PythonSoftwareFoundation.Python.3.11_qbz5n2kfra8p0\LocalCache\local-packages\Python311\site-packages\pymysql\connections.py", line 453, in _read_ok_packet
    pkt = self._read_packet()
          ^^^^^^^^^^^^^^^^^^^
  File "C:\Users\singh\AppData\Local\Packages\PythonSoftwareFoundation.Python.3.11_qbz5n2kfra8p0\LocalCache\local-packages\Python311\site-packages\pymysql\connections.py", line 744, in _read_packet
    packet_header = self._read_bytes(4)
                    ^^^^^^^^^^^^^^^^^^^
  File "C:\Users\singh\AppData\Local\Packages\PythonSoftwareFoundation.Python.3.11_qbz5n2kfra8p0\LocalCache\local-packages\Python311\site-packages\pymysql\connections.py", line 782, in _read_bytes
    data = self._rfile.read(num_bytes)
           ^^^^^^^^^^^^^^^^^^^^^^^^^^^
  File "C:\Program Files\WindowsApps\PythonSoftwareFoundation.Python.3.11_3.11.2544.0_x64__qbz5n2kfra8p0\Lib\socket.py", line 706, in readinto
    return self._sock.recv_into(b)
           ^^^^^^^^^^^^^^^^^^^^^^^
KeyboardInterrupt
2025-09-26 23:44:40,415 - INFO - Data lod
2025-09-26 23:44:54,766 - INFO - Data lod
2025-09-26 23:45:08,319 - INFO - Data loaded in the df
2025-09-26 23:45:43,819 - INFO - All the required credential is fetched from yaml file
2025-09-26 23:46:05,646 - ERROR - Oh no
2025-09-26 23:47:19,828 - INFO - Created Engine.
2025-09-26 23:47:38,552 - INFO - Data loaded in the df
2025-09-26 23:47:38,610 - INFO - All the required credential is fetched from yaml file
2025-09-26 23:47:38,620 - ERROR - Oh no
2025-09-26 23:47:38,633 - INFO - Created Engine.
2025-09-26 23:51:22,831 - INFO - Data loaded in the df
2025-09-26 23:51:25,547 - INFO - All the required credential is fetched from yaml file
2025-09-26 23:51:26,675 - ERROR - Oh no
2025-09-26 23:51:27,800 - INFO - Created Engine.
2025-09-26 23:52:23,633 - INFO - Data loaded in the df
2025-09-26 23:52:25,119 - INFO - All the required credential is fetched from yaml file
2025-09-26 23:52:26,411 - ERROR - Oh no
2025-09-26 23:52:28,573 - INFO - Created Engine.
2025-09-26 23:52:31,559 - INFO - Created Engine and connected successfully.
2025-09-26 23:59:02,655 - INFO - Data loaded in the df
